Workbook

Sheet Параметры
A1: ПАРАМЕТРЫ ОБЪЕКТА (редактируйте синие ячейки на жёлтом фоне)
A3: Параметр | B3: Значение | C3: Комментарий
A4: Общая площадь квартиры, м² (с лоджией) | B4: 55.1 | C4: по плану кв. 312: жилая 25.4 / общая 52.4 / с лоджией 55.1
A5: Площадь пола под ламинат/SPC, м² | B5: 42 | C5: спальня 11.7 + гостиная/детская 13.7 + кухня 10.3 + часть прихожей ≈ 6 (у входа — керамогранит, видно на видео)
A6: Запас на подрезку, % | B6: 0.07 | C6: 7% для прямой укладки, 10–12% для диагонали/ёлочки
A7: Площадь натяжных потолков, м² | B7: 52.4 | C7: по плану: 13.7+11.7+10.3+11.8+2.8+2.1 (лоджия не считается)
A8: Периметр плинтуса, п.м | B8: 50 | C8: спальня ≈14 + детская ≈15 + кухня-гостиная ≈21 п.м
A9: Розетки, шт | B9: 30 | C9: типовая 2-комн. 55 м²: кухня 8–10, комнаты 6–8 каждая, коридор 2, санузлы 2
A10: Выключатели, шт | B10: 8
A11: Рамки, шт | B11: 25 | C11: часть розеток блоками по 2–3 в одной рамке
A12: Точки света на потолке, шт | B12: 12 | C12: точечные/трек + люстры; уточнить по вашему плану
A13: Санузлов, шт | B13: 2 | C13: по видео: №1 с унитазом и колонкой, №2 с душевым подиумом
A14: Раковин, шт | B14: 2 | C14: по одной в каждый санузел
A15: Площадь стен под обои, м² | B15: 120 | C15: периметр ≈ 52 п.м (после сноса стены кухня–прихожая) × h 2.7 = 140 минус окна и проёмы ≈ 20; санузлы в плитке
A16: Дверей стандартных 800 мм, шт | B16: 3 | C16: спальня, ванная, с/у (кухня — стена снесена, двери нет)
A17: Дверей широких (детская, проём расширен), шт | B17: 1 | C17: двустворчатая или раздвижная — по заметке брата проём сделан широким
A18: Резерв на непредвиденное, % | B18: 0.1 | C18: рекомендуется 10–15%
A21: Легенда:
A22: Синий текст на жёлтом — вводные, которые вы меняете. Чёрный — формулы. Зелёный — ссылки на другой лист.
A23: Цены — ориентир по Саратову на сентябрь 2026 (Лемана ПРО Саратов, Профком, Сантехника.ру Саратов, Profi.ru Саратов, сайты потолочных компаний). Перед закупкой сверьте по ссылкам на листе «Закупка_ссылки».

Sheet 1_Ремонт
A1: 1. РЕМОНТ: ПОЛ, ПОТОЛКИ, САНТЕХНИКА, ЭЛЕКТРИКА, ОБОИ, ДВЕРИ — 3 ОПЦИИ + РЕАЛ — квартира 55 м², Саратов, сентябрь 2026
A2: Цены за единицу (F, H, J) — синие, правьте. Столбец M «Выбор РЕАЛ» — выпадающий список МИН/СРЕД/МАКС для реалистичной сборки, столбец N считает её сумму.
A4: № | B4: Раздел | C4: Позиция | D4: Ед. | E4: Кол-во | F4: Цена МИН | G4: Сумма МИН | H4: Цена СРЕД | I4: Сумма СРЕД | J4: Цена МАКС | K4: Сумма МАКС | L4: Примечание | M4: Выбор РЕАЛ | N4: Сумма РЕАЛ
A5: 1. ПОЛ — материалы
A6: 1 | B6: 1. Пол | C6: Напольное покрытие (ламинат / SPC) | D6: м² | E6: =ROUND(Параметры!$B$5*(1+Параметры!$B$6),0) -> 45 | F6: 700 | G6: =E6*F6 -> 31500 | H6: 1150 | I6: =E6*H6 -> 51750 | J6: 2300 | K6: =E6*J6 -> 103500 | L6: МИН: ламинат 32 кл 8 мм · СРЕД: ламинат 33 кл 8–10 мм влагостойкий с фаской · МАКС: SPC-кварцвинил 43 кл 4–5 мм | M6: СРЕД | N6: =IF(M6="МИН",G6,IF(M6="МАКС",K6,I6)) -> 51750
A7: 2 | B7: 1. Пол | C7: Подложка | D7: м² | E7: =ROUND(Параметры!$B$5*(1+Параметры!$B$6),0) -> 45 | F7: 100 | G7: =E7*F7 -> 4500 | H7: 200 | I7: =E7*H7 -> 9000 | J7: 350 | K7: =E7*J7 -> 15750 | L7: МИН: вспененный ПЭ 2 мм · СРЕД: XPS/Arbiton 3 мм · МАКС: пробка/IXPE 1.5 мм под SPC | M7: СРЕД | N7: =IF(M7="МИН",G7,IF(M7="МАКС",K7,I7)) -> 9000
A8: 3 | B8: 1. Пол | C8: Плёнка пароизоляция 200 мкм | D8: м² | E8: =ROUND(Параметры!$B$5*(1+Параметры!$B$6),0) -> 45 | F8: 30 | G8: =E8*F8 -> 1350 | H8: 40 | I8: =E8*H8 -> 1800 | J8: 40 | K8: =E8*J8 -> 1800 | L8: по стяжке обязательно | M8: СРЕД | N8: =IF(M8="МИН",G8,IF(M8="МАКС",K8,I8)) -> 1800
A9: 4 | B9: 1. Пол | C9: Плинтус напольный | D9: п.м | E9: =Параметры!$B$8 -> 50 | F9: 130 | G9: =E9*F9 -> 6500 | H9: 350 | I9: =E9*H9 -> 17500 | J9: 800 | K9: =E9*J9 -> 40000 | L9: МИН: ПВХ с кабель-каналом · СРЕД: МДФ/дюрополимер 80 мм · МАКС: скрытый алюминиевый / дюрополимер под покраску 100 мм | M9: СРЕД | N9: =IF(M9="МИН",G9,IF(M9="МАКС",K9,I9)) -> 17500
A10: 5 | B10: 1. Пол | C10: Порожки, стыки плитка–ламинат | D10: компл | E10: 1 | F10: 1500 | G10: =E10*F10 -> 1500 | H10: 3000 | I10: =E10*H10 -> 3000 | J10: 6000 | K10: =E10*J10 -> 6000 | L10: у входов в коридор и санузлы (по видео там керамогранит) | M10: СРЕД | N10: =IF(M10="МИН",G10,IF(M10="МАКС",K10,I10)) -> 3000
A11: 2. ПОТОЛОК — материалы и потолок «под ключ»
A12: 6 | B12: 2. Потолок | C12: Натяжной потолок с монтажом «под ключ» | D12: м² | E12: =Параметры!$B$7 -> 52.4 | F12: 400 | G12: =E12*F12 -> 20960 | H12: 950 | I12: =E12*H12 -> 49780 | J12: 1800 | K12: =E12*J12 -> 94320 | L12: МИН: ПВХ матовый MSD · СРЕД: Bauf/тканевый + теневой профиль · МАКС: тканевый Descor + теневой профиль + парящий/световые линии | M12: СРЕД | N12: =IF(M12="МИН",G12,IF(M12="МАКС",K12,I12)) -> 49780
A13: 7 | B13: 2. Потолок | C13: Закладные (брус/платформы) под люстры, карнизы | D13: компл | E13: 1 | F13: 2000 | G13: =E13*F13 -> 2000 | H13: 4000 | I13: =E13*H13 -> 4000 | J13: 8000 | K13: =E13*J13 -> 8000 | L13: ставится ДО натяжки | M13: СРЕД | N13: =IF(M13="МИН",G13,IF(M13="МАКС",K13,I13)) -> 4000
A14: 8 | B14: 2. Потолок | C14: Кабель ВВГнг-LS + гофра для потолочных линий | D14: компл | E14: 1 | F14: 6000 | G14: =E14*F14 -> 6000 | H14: 12000 | I14: =E14*H14 -> 12000 | J14: 20000 | K14: =E14*J14 -> 20000 | M14: СРЕД | N14: =IF(M14="МИН",G14,IF(M14="МАКС",K14,I14)) -> 12000
A15: 9 | B15: 2. Потолок | C15: Светильники потолочные | D15: шт | E15: =Параметры!$B$12 -> 12 | F15: 250 | G15: =E15*F15 -> 3000 | H15: 700 | I15: =E15*H15 -> 8400 | J15: 2500 | K15: =E15*J15 -> 30000 | L15: МИН: GX53 накладные · СРЕД: точечные LED + 2 люстры · МАКС: магнитный трек + дизайнерские | M15: СРЕД | N15: =IF(M15="МИН",G15,IF(M15="МАКС",K15,I15)) -> 8400
A16: 10 | B16: 2. Потолок | C16: Ниша ГКЛ под скрытый карниз (материалы) | D16: компл | E16: 1 | F16: 0 | G16: =E16*F16 -> 0 | H16: 5000 | I16: =E16*H16 -> 5000 | J16: 12000 | K16: =E16*J16 -> 12000 | L16: в МИН не делаем — карниз накладной | M16: СРЕД | N16: =IF(M16="МИН",G16,IF(M16="МАКС",K16,I16)) -> 5000
A17: 3. САНТЕХНИКА — материалы
A18: 11 | B18: 3. Сантехника | C18: Унитаз | D18: шт | E18: 1 | F18: 8000 | G18: =E18*F18 -> 8000 | H18: 18000 | I18: =E18*H18 -> 18000 | J18: 45000 | K18: =E18*J18 -> 45000 | L18: МИН: компакт Cersanit Trento · СРЕД: безободковый с микролифтом Cersanit City / Roca Gap · МАКС: инсталляция Geberit Duofix + подвесной Geberit iCon/Roca | M18: СРЕД | N18: =IF(M18="МИН",G18,IF(M18="МАКС",K18,I18)) -> 18000
A19: 12 | B19: 3. Сантехника | C19: Раковина (умывальник) | D19: шт | E19: =Параметры!$B$14 -> 2 | F19: 3000 | G19: =E19*F19 -> 6000 | H19: 8000 | I19: =E19*H19 -> 16000 | J19: 18000 | K19: =E19*J19 -> 36000 | M19: СРЕД | N19: =IF(M19="МИН",G19,IF(M19="МАКС",K19,I19)) -> 16000
A20: 13 | B20: 3. Сантехника | C20: Смеситель для раковины | D20: шт | E20: =Параметры!$B$14 -> 2 | F20: 2500 | G20: =E20*F20 -> 5000 | H20: 7000 | I20: =E20*H20 -> 14000 | J20: 18000 | K20: =E20*J20 -> 36000 | L20: МИН: Iddis/Esko · СРЕД: Lemark Plus / Grohe BauEdge · МАКС: Hansgrohe Talis / Grohe Essence | M20: СРЕД | N20: =IF(M20="МИН",G20,IF(M20="МАКС",K20,I20)) -> 14000
A21: 14 | B21: 3. Сантехника | C21: Сифон + подводки для раковины | D21: шт | E21: =Параметры!$B$14 -> 2 | F21: 700 | G21: =E21*F21 -> 1400 | H21: 1500 | I21: =E21*H21 -> 3000 | J21: 3500 | K21: =E21*J21 -> 7000 | M21: СРЕД | N21: =IF(M21="МИН",G21,IF(M21="МАКС",K21,I21)) -> 3000
A22: 15 | B22: 3. Сантехника | C22: Тумба под раковину | D22: шт | E22: =Параметры!$B$14 -> 2 | F22: 6000 | G22: =E22*F22 -> 12000 | H22: 18000 | I22: =E22*H22 -> 36000 | J22: 45000 | K22: =E22*J22 -> 90000 | L22: МИН: Sensea/Runo · СРЕД: Aquaton/Style Line · МАКС: Jacob Delafon / Cezares | M22: СРЕД | N22: =IF(M22="МИН",G22,IF(M22="МАКС",K22,I22)) -> 36000
A23: 16 | B23: 3. Сантехника | C23: Смеситель для душа + душевая стойка | D23: компл | E23: 1 | F23: 4000 | G23: =E23*F23 -> 4000 | H23: 15000 | I23: =E23*H23 -> 15000 | J23: 45000 | K23: =E23*J23 -> 45000 | L23: выводы под смеситель на видео готовы (открытый монтаж) | M23: СРЕД | N23: =IF(M23="МИН",G23,IF(M23="МАКС",K23,I23)) -> 15000
A24: 17 | B24: 3. Сантехника | C24: Ограждение душевого подиума | D24: шт | E24: 1 | F24: 3000 | G24: =E24*F24 -> 3000 | H24: 30000 | I24: =E24*H24 -> 30000 | J24: 60000 | K24: =E24*J24 -> 60000 | L24: МИН: штанга + шторка · СРЕД: стекло 8 мм на заказ (Walk-In) · МАКС: стекло 10 мм + дверь, чёрная/латунная фурнитура | M24: СРЕД | N24: =IF(M24="МИН",G24,IF(M24="МАКС",K24,I24)) -> 30000
A25: 18 | B25: 3. Сантехника | C25: Гигиенический душ | D25: компл | E25: 1 | F25: 2500 | G25: =E25*F25 -> 2500 | H25: 7000 | I25: =E25*H25 -> 7000 | J25: 15000 | K25: =E25*J25 -> 15000 | M25: СРЕД | N25: =IF(M25="МИН",G25,IF(M25="МАКС",K25,I25)) -> 7000
A26: 19 | B26: 3. Сантехника | C26: Полотенцесушитель электрический | D26: шт | E26: 1 | F26: 4000 | G26: =E26*F26 -> 4000 | H26: 12000 | I26: =E26*H26 -> 12000 | J26: 25000 | K26: =E26*J26 -> 25000 | L26: электрический — под него нужна розетка/вывод | M26: СРЕД | N26: =IF(M26="МИН",G26,IF(M26="МАКС",K26,I26)) -> 12000
A27: 20 | B27: 3. Сантехника | C27: Зеркало / зеркальный шкаф | D27: шт | E27: =Параметры!$B$14 -> 2 | F27: 1500 | G27: =E27*F27 -> 3000 | H27: 6000 | I27: =E27*H27 -> 12000 | J27: 15000 | K27: =E27*J27 -> 30000 | M27: СРЕД | N27: =IF(M27="МИН",G27,IF(M27="МАКС",K27,I27)) -> 12000
A28: 21 | B28: 3. Сантехника | C28: Вентилятор вытяжной | D28: шт | E28: =Параметры!$B$13 -> 2 | F28: 800 | G28: =E28*F28 -> 1600 | H28: 3000 | I28: =E28*H28 -> 6000 | J28: 7000 | K28: =E28*J28 -> 14000 | L28: МАКС: Soler&Palau Silent с таймером | M28: СРЕД | N28: =IF(M28="МИН",G28,IF(M28="МАКС",K28,I28)) -> 6000
A29: 22 | B29: 3. Сантехника | C29: Аксессуары (держатели, ёршик, крючки, дозатор) | D29: компл | E29: 1 | F29: 2500 | G29: =E29*F29 -> 2500 | H29: 7000 | I29: =E29*H29 -> 7000 | J29: 20000 | K29: =E29*J29 -> 20000 | M29: СРЕД | N29: =IF(M29="МИН",G29,IF(M29="МАКС",K29,I29)) -> 7000
A30: 23 | B30: 3. Сантехника | C30: Люк ревизионный к колонке/стоякам | D30: шт | E30: 1 | F30: 2000 | G30: =E30*F30 -> 2000 | H30: 5000 | I30: =E30*H30 -> 5000 | J30: 12000 | K30: =E30*J30 -> 12000 | L30: МАКС: нажимной скрытый под плитку | M30: СРЕД | N30: =IF(M30="МИН",G30,IF(M30="МАКС",K30,I30)) -> 5000
A31: 24 | B31: 3. Сантехника | C31: Расходники (краны, гибкая подводка, ФУМ, силикон) | D31: компл | E31: 1 | F31: 3000 | G31: =E31*F31 -> 3000 | H31: 6000 | I31: =E31*H31 -> 6000 | J31: 10000 | K31: =E31*J31 -> 10000 | M31: СРЕД | N31: =IF(M31="МИН",G31,IF(M31="МАКС",K31,I31)) -> 6000
A32: 4. ЭЛЕКТРИКА — материалы
A33: 25 | B33: 4. Электрика | C33: Розетка (механизм) | D33: шт | E33: =Параметры!$B$9 -> 30 | F33: 200 | G33: =E33*F33 -> 6000 | H33: 900 | I33: =E33*H33 -> 27000 | J33: 2200 | K33: =E33*J33 -> 66000 | L33: МИН: Systeme Electric Этюд/Glossa · СРЕД: Werkel / AtlasDesign · МАКС: Legrand Valena Life / Jung / Gira | M33: СРЕД | N33: =IF(M33="МИН",G33,IF(M33="МАКС",K33,I33)) -> 27000
A34: 26 | B34: 4. Электрика | C34: Выключатель (механизм) | D34: шт | E34: =Параметры!$B$10 -> 8 | F34: 200 | G34: =E34*F34 -> 1600 | H34: 900 | I34: =E34*H34 -> 7200 | J34: 2500 | K34: =E34*J34 -> 20000 | M34: СРЕД | N34: =IF(M34="МИН",G34,IF(M34="МАКС",K34,I34)) -> 7200
A35: 27 | B35: 4. Электрика | C35: Рамки | D35: шт | E35: =Параметры!$B$11 -> 25 | F35: 60 | G35: =E35*F35 -> 1500 | H35: 250 | I35: =E35*H35 -> 6250 | J35: 800 | K35: =E35*J35 -> 20000 | M35: СРЕД | N35: =IF(M35="МИН",G35,IF(M35="МАКС",K35,I35)) -> 6250
A36: 28 | B36: 4. Электрика | C36: Подрозетники | D36: шт | E36: =Параметры!$B$9+Параметры!$B$10 -> 38 | F36: 60 | G36: =E36*F36 -> 2280 | H36: 60 | I36: =E36*H36 -> 2280 | J36: 60 | K36: =E36*J36 -> 2280 | L36: если уже вмурованы — поставьте 0 | M36: СРЕД | N36: =IF(M36="МИН",G36,IF(M36="МАКС",K36,I36)) -> 2280
A37: 29 | B37: 4. Электрика | C37: Щит в сборе (бокс, автоматы, УЗО/дифы, реле напряжения) | D37: компл | E37: 1 | F37: 8000 | G37: =E37*F37 -> 8000 | H37: 25000 | I37: =E37*H37 -> 25000 | J37: 60000 | K37: =E37*J37 -> 60000 | L37: МИН: IEK/EKF · СРЕД: Schneider Easy9 / ABB Basic M + реле напряжения · МАКС: ABB S200 / Hager + дифавтоматы + УЗИП | M37: СРЕД | N37: =IF(M37="МИН",G37,IF(M37="МАКС",K37,I37)) -> 25000
A38: 30 | B38: 4. Электрика | C38: Кабель на доделку линий | D38: компл | E38: 1 | F38: 3000 | G38: =E38*F38 -> 3000 | H38: 6000 | I38: =E38*H38 -> 6000 | J38: 10000 | K38: =E38*J38 -> 10000 | M38: СРЕД | N38: =IF(M38="МИН",G38,IF(M38="МАКС",K38,I38)) -> 6000
A39: 31 | B39: 4. Электрика | C39: Выделенная линия на электроварочную (ВВГнг 3×6 + автомат 32А + розетка 32А) | D39: компл | E39: 1 | F39: 3500 | G39: =E39*F39 -> 3500 | H39: 4500 | I39: =E39*H39 -> 4500 | J39: 6000 | K39: =E39*J39 -> 6000 | L39: варочная электрическая — обязательна отдельная линия от щита | M39: СРЕД | N39: =IF(M39="МИН",G39,IF(M39="МАКС",K39,I39)) -> 4500
A40: 5. ФИНИШ СТЕН (ОБОИ) — материалы
A41: 32 | B41: 5. Стены | C41: Обои | D41: м² | E41: =Параметры!$B$15 -> 120 | F41: 200 | G41: =E41*F41 -> 24000 | H41: 450 | I41: =E41*H41 -> 54000 | J41: 1200 | K41: =E41*J41 -> 144000 | L41: МИН: виниловые на флизелине (Лемана, ~1 100 ₽/рулон 5.3 м²) · СРЕД: флизелиновые Erismann/Marburg, под подбор рисунка · МАКС: дизайнерские/текстильные, широкий рулон. Расход ≈ +10% на подбор | M41: СРЕД | N41: =IF(M41="МИН",G41,IF(M41="МАКС",K41,I41)) -> 54000
...

Sheet 2_Заезд
A1: 2. ЧТОБЫ ЗАЕХАТЬ: КУХНЯ, СПАЛЬНЯ, ДЕТСКАЯ, ЗАЛ, ПРИХОЖАЯ, ТЕХНИКА — 3 ОПЦИИ
A2: Цены (F, H, J) и количество (E) — синие, правьте. Ссылки — столбец M. Столбец N «Выбор РЕАЛ» — выпадающий список МИН/СРЕД/МАКС, столбец O — сумма реалистичной сборки.
A4: № | B4: Раздел | C4: Позиция | D4: Ед. | E4: Кол-во | F4: Цена МИН | G4: Сумма МИН | H4: Цена СРЕД | I4: Сумма СРЕД | J4: Цена МАКС | K4: Сумма МАКС | L4: Примечание | M4: Где купить | N4: Выбор РЕАЛ | O4: Сумма РЕАЛ
A5: К. КУХНЯ
A6: 1 | B6: Кухня | C6: Кухонный гарнитур | D6: компл | E6: 1 | F6: 70000 | G6: =E6*F6 -> 70000 | H6: 150000 | I6: =E6*H6 -> 150000 | J6: 450000 | K6: =E6*J6 -> 450000 | L6: МИН: модульная Hoff «Амика»/«Барселона» 2.4–3 м или Лемана Delinia · СРЕД: Hoff на заказ (студия планирования в Happy Молл, Саратов) / Лемана на заказ, ЛДСП+МДФ-плёнка · МАКС: фабрика «Мария» | M6: https://hoff.ru/catalog/kukhonnye-garnitury/modulnye-kukhonnye-garnitury/ | N6: МИН | O6: =IF(N6="МИН",G6,IF(N6="МАКС",K6,I6)) -> 70000
A7: 2 | B7: Кухня | C7: Столешница | D7: компл | E7: 1 | F7: 8000 | G7: =E7*F7 -> 8000 | H7: 20000 | I7: =E7*H7 -> 20000 | J7: 90000 | K7: =E7*J7 -> 90000 | L7: МИН: ЛДСП 28 мм Лемана/Hoff · СРЕД: ЛДСП 38 мм / компакт-плита · МАКС: кварцевый агломерат | M7: https://hoff.ru/catalog/kuhnya/kuhonnye_garnitury/ | N7: МИН | O7: =IF(N7="МИН",G7,IF(N7="МАКС",K7,I7)) -> 8000
A8: 3 | B8: Кухня | C8: Фартук (плитка / стекло / компакт) | D8: компл | E8: 1 | F8: 5000 | G8: =E8*F8 -> 5000 | H8: 15000 | I8: =E8*H8 -> 15000 | J8: 35000 | K8: =E8*J8 -> 35000 | L8: по видео стена кухни без фартука | M8: https://saratov.lemanapro.ru/ | N8: СРЕД | O8: =IF(N8="МИН",G8,IF(N8="МАКС",K8,I8)) -> 15000
A9: 4 | B9: Кухня | C9: Мойка + смеситель | D9: компл | E9: 1 | F9: 6000 | G9: =E9*F9 -> 6000 | H9: 18000 | I9: =E9*H9 -> 18000 | J9: 45000 | K9: =E9*J9 -> 45000 | L9: МИН: нерж. накладная · СРЕД: врезная гранит + Lemark · МАКС: Blanco/Omoikiri + Grohe | M9: https://saratov.lemanapro.ru/ | N9: СРЕД | O9: =IF(N9="МИН",G9,IF(N9="МАКС",K9,I9)) -> 18000
A10: 5 | B10: Кухня | C10: Варочная панель электрическая (индукция) | D10: шт | E10: 1 | F10: 12000 | G10: =E10*F10 -> 12000 | H10: 30000 | I10: =E10*H10 -> 30000 | J10: 70000 | K10: =E10*J10 -> 70000 | L10: МИН: Hansa/Weissgauff стеклокерамика · СРЕД: Bosch/Electrolux индукция · МАКС: Bosch Serie 8 / Miele. Нужна отдельная линия 32А — учтена на листе 1_Ремонт | M10: https://www.dns-shop.ru/?city=saratov | N10: СРЕД | O10: =IF(N10="МИН",G10,IF(N10="МАКС",K10,I10)) -> 30000
A11: 6 | B11: Кухня | C11: Духовой шкаф | D11: шт | E11: 1 | F11: 20000 | G11: =E11*F11 -> 20000 | H11: 40000 | I11: =E11*H11 -> 40000 | J11: 90000 | K11: =E11*J11 -> 90000 | M11: https://www.dns-shop.ru/?city=saratov | N11: МИН | O11: =IF(N11="МИН",G11,IF(N11="МАКС",K11,I11)) -> 20000
A12: 7 | B12: Кухня | C12: Вытяжка | D12: шт | E12: 1 | F12: 5000 | G12: =E12*F12 -> 5000 | H12: 15000 | I12: =E12*H12 -> 15000 | J12: 40000 | K12: =E12*J12 -> 40000 | M12: https://www.dns-shop.ru/?city=saratov | N12: МИН | O12: =IF(N12="МИН",G12,IF(N12="МАКС",K12,I12)) -> 5000
A13: 8 | B13: Кухня | C13: Холодильник | D13: шт | E13: 1 | F13: 35000 | G13: =E13*F13 -> 35000 | H13: 70000 | I13: =E13*H13 -> 70000 | J13: 180000 | K13: =E13*J13 -> 180000 | L13: МИН: Indesit/Atlant · СРЕД: Haier/LG NoFrost · МАКС: Bosch/Liebherr | M13: https://www.dns-shop.ru/?city=saratov | N13: СРЕД | O13: =IF(N13="МИН",G13,IF(N13="МАКС",K13,I13)) -> 70000
A14: 9 | B14: Кухня | C14: Посудомоечная машина | D14: шт | E14: 1 | F14: 0 | G14: =E14*F14 -> 0 | H14: 35000 | I14: =E14*H14 -> 35000 | J14: 80000 | K14: =E14*J14 -> 80000 | L14: в МИН не берём | M14: https://www.dns-shop.ru/?city=saratov | N14: СРЕД | O14: =IF(N14="МИН",G14,IF(N14="МАКС",K14,I14)) -> 35000
A15: 10 | B15: Кухня | C15: Микроволновка | D15: шт | E15: 1 | F15: 6000 | G15: =E15*F15 -> 6000 | H15: 12000 | I15: =E15*H15 -> 12000 | J15: 30000 | K15: =E15*J15 -> 30000 | M15: https://www.dns-shop.ru/?city=saratov | N15: МИН | O15: =IF(N15="МИН",G15,IF(N15="МАКС",K15,I15)) -> 6000
A16: 11 | B16: Кухня | C16: Обеденный стол + стулья (4 шт) | D16: компл | E16: 1 | F16: 12000 | G16: =E16*F16 -> 12000 | H16: 35000 | I16: =E16*H16 -> 35000 | J16: 100000 | K16: =E16*J16 -> 100000 | L16: Hoff Саратов — Happy Молл, Вольский тракт 2 | M16: https://hoff.ru/catalog/mebel/ | N16: МИН | O16: =IF(N16="МИН",G16,IF(N16="МАКС",K16,I16)) -> 12000
A17: 12 | B17: Кухня | C17: Посуда, кухонная утварь, текстиль | D17: компл | E17: 1 | F17: 8000 | G17: =E17*F17 -> 8000 | H17: 20000 | I17: =E17*H17 -> 20000 | J17: 50000 | K17: =E17*J17 -> 50000 | M17: https://hoff.ru/catalog/mebel/ | N17: МИН | O17: =IF(N17="МИН",G17,IF(N17="МАКС",K17,I17)) -> 8000
A18: С. СПАЛЬНЯ
A19: 13 | B19: Спальня | C19: Кровать 160×200 с основанием | D19: шт | E19: 1 | F19: 15000 | G19: =E19*F19 -> 15000 | H19: 40000 | I19: =E19*H19 -> 40000 | J19: 120000 | K19: =E19*J19 -> 120000 | L19: МИН: Hoff/Шатура ЛДСП · СРЕД: мягкое изголовье, подъёмный механизм · МАКС: Аскона/массив | M19: https://hoff.ru/catalog/mebel/ | N19: МИН | O19: =IF(N19="МИН",G19,IF(N19="МАКС",K19,I19)) -> 15000
A20: 14 | B20: Спальня | C20: Матрас 160×200 | D20: шт | E20: 1 | F20: 12000 | G20: =E20*F20 -> 12000 | H20: 30000 | I20: =E20*H20 -> 30000 | J20: 80000 | K20: =E20*J20 -> 80000 | L20: МИН: пружинный · СРЕД: независимые пружины Аскона · МАКС: ортопедический премиум | M20: https://hoff.ru/catalog/mebel/ | N20: СРЕД | O20: =IF(N20="МИН",G20,IF(N20="МАКС",K20,I20)) -> 30000
A21: 15 | B21: Спальня | C21: Шкаф для одежды | D21: шт | E21: 1 | F21: 20000 | G21: =E21*F21 -> 20000 | H21: 60000 | I21: =E21*H21 -> 60000 | J21: 180000 | K21: =E21*J21 -> 180000 | L21: МИН: распашной ЛДСП · СРЕД: купе 2 м · МАКС: встроенный на заказ | M21: https://hoff.ru/catalog/mebel/ | N21: МИН | O21: =IF(N21="МИН",G21,IF(N21="МАКС",K21,I21)) -> 20000
A22: 16 | B22: Спальня | C22: Прикроватные тумбы | D22: шт | E22: 2 | F22: 3000 | G22: =E22*F22 -> 6000 | H22: 8000 | I22: =E22*H22 -> 16000 | J22: 25000 | K22: =E22*J22 -> 50000 | M22: https://hoff.ru/catalog/mebel/ | N22: МИН | O22: =IF(N22="МИН",G22,IF(N22="МАКС",K22,I22)) -> 6000
A23: 17 | B23: Спальня | C23: Комод | D23: шт | E23: 1 | F23: 8000 | G23: =E23*F23 -> 8000 | H23: 20000 | I23: =E23*H23 -> 20000 | J23: 50000 | K23: =E23*J23 -> 50000 | M23: https://hoff.ru/catalog/mebel/ | N23: МИН | O23: =IF(N23="МИН",G23,IF(N23="МАКС",K23,I23)) -> 8000
A24: 18 | B24: Спальня | C24: Шторы + карниз | D24: компл | E24: 1 | F24: 5000 | G24: =E24*F24 -> 5000 | H24: 15000 | I24: =E24*H24 -> 15000 | J24: 40000 | K24: =E24*J24 -> 40000 | L24: СРЕД/МАКС — под скрытый карниз в потолке (см. лист 1_Ремонт) | M24: https://hoff.ru/catalog/mebel/ | N24: МИН | O24: =IF(N24="МИН",G24,IF(N24="МАКС",K24,I24)) -> 5000
A25: 19 | B25: Спальня | C25: Постельное, подушки, одеяло | D25: компл | E25: 1 | F25: 5000 | G25: =E25*F25 -> 5000 | H25: 12000 | I25: =E25*H25 -> 12000 | J25: 30000 | K25: =E25*J25 -> 30000 | M25: https://hoff.ru/catalog/mebel/ | N25: МИН | O25: =IF(N25="МИН",G25,IF(N25="МАКС",K25,I25)) -> 5000
A26: 20 | B26: Спальня | C26: Бра / настольные светильники | D26: компл | E26: 1 | F26: 2000 | G26: =E26*F26 -> 2000 | H26: 8000 | I26: =E26*H26 -> 8000 | J26: 25000 | K26: =E26*J26 -> 25000 | M26: https://saratov.lemanapro.ru/ | N26: МИН | O26: =IF(N26="МИН",G26,IF(N26="МАКС",K26,I26)) -> 2000
A27: Д. ДЕТСКАЯ
A28: 21 | B28: Детская | C28: Кровать раздвижная (растущая) 80×130→190 | D28: шт | E28: 1 | F28: 12000 | G28: =E28*F28 -> 12000 | H28: 35000 | I28: =E28*H28 -> 35000 | J28: 90000 | K28: =E28*J28 -> 90000 | L28: МИН: раздвижная ЛДСП Hoff/Шатура · СРЕД: с ящиками и мягким изголовьем (Аскона/Hoff) · МАКС: на заказ / массив. Матрас — тоже раздвижной/секционный | M28: https://hoff.ru/catalog/mebel/ | N28: СРЕД | O28: =IF(N28="МИН",G28,IF(N28="МАКС",K28,I28)) -> 35000
A29: 22 | B29: Детская | C29: Матрас для раздвижной кровати (секционный) | D29: шт | E29: 1 | F29: 7000 | G29: =E29*F29 -> 7000 | H29: 18000 | I29: =E29*H29 -> 18000 | J29: 45000 | K29: =E29*J29 -> 45000 | L29: секции 80×130 + 80×60 или два матраса | M29: https://hoff.ru/catalog/mebel/ | N29: СРЕД | O29: =IF(N29="МИН",G29,IF(N29="МАКС",K29,I29)) -> 18000
A30: 23 | B30: Детская | C30: Письменный стол + стул | D30: компл | E30: 1 | F30: 8000 | G30: =E30*F30 -> 8000 | H30: 25000 | I30: =E30*H30 -> 25000 | J30: 60000 | K30: =E30*J30 -> 60000 | L30: СРЕД/МАКС — растущий стол, ортопедический стул | M30: https://hoff.ru/catalog/mebel/ | N30: СРЕД | O30: =IF(N30="МИН",G30,IF(N30="МАКС",K30,I30)) -> 25000
A31: 24 | B31: Детская | C31: Шкаф | D31: шт | E31: 1 | F31: 15000 | G31: =E31*F31 -> 15000 | H31: 40000 | I31: =E31*H31 -> 40000 | J31: 120000 | K31: =E31*J31 -> 120000 | M31: https://hoff.ru/catalog/mebel/ | N31: МИН | O31: =IF(N31="МИН",G31,IF(N31="МАКС",K31,I31)) -> 15000
A32: 25 | B32: Детская | C32: Стеллаж / полки | D32: шт | E32: 1 | F32: 5000 | G32: =E32*F32 -> 5000 | H32: 15000 | I32: =E32*H32 -> 15000 | J32: 40000 | K32: =E32*J32 -> 40000 | M32: https://hoff.ru/catalog/mebel/ | N32: МИН | O32: =IF(N32="МИН",G32,IF(N32="МАКС",K32,I32)) -> 5000
A33: 26 | B33: Детская | C33: Шторы + карниз | D33: компл | E33: 1 | F33: 4000 | G33: =E33*F33 -> 4000 | H33: 12000 | I33: =E33*H33 -> 12000 | J33: 30000 | K33: =E33*J33 -> 30000 | M33: https://hoff.ru/catalog/mebel/ | N33: МИН | O33: =IF(N33="МИН",G33,IF(N33="МАКС",K33,I33)) -> 4000
A34: 27 | B34: Детская | C34: Ковёр | D34: шт | E34: 1 | F34: 3000 | G34: =E34*F34 -> 3000 | H34: 10000 | I34: =E34*H34 -> 10000 | J34: 30000 | K34: =E34*J34 -> 30000 | M34: https://hoff.ru/catalog/mebel/ | N34: МИН | O34: =IF(N34="МИН",G34,IF(N34="МАКС",K34,I34)) -> 3000
A35: 28 | B35: Детская | C35: Текстиль (постельное, подушки) | D35: компл | E35: 1 | F35: 3000 | G35: =E35*F35 -> 3000 | H35: 8000 | I35: =E35*H35 -> 8000 | J35: 20000 | K35: =E35*J35 -> 20000 | M35: https://hoff.ru/catalog/mebel/ | N35: МИН | O35: =IF(N35="МИН",G35,IF(N35="МАКС",K35,I35)) -> 3000
A36: 29 | B36: Детская | C36: Освещение (настольная лампа, ночник) | D36: компл | E36: 1 | F36: 2000 | G36: =E36*F36 -> 2000 | H36: 6000 | I36: =E36*H36 -> 6000 | J36: 15000 | K36: =E36*J36 -> 15000 | M36: https://saratov.lemanapro.ru/ | N36: МИН | O36: =IF(N36="МИН",G36,IF(N36="МАКС",K36,I36)) -> 2000
A37: З. ЗАЛ
A38: 30 | B38: Зал | C38: Диван | D38: шт | E38: 1 | F38: 25000 | G38: =E38*F38 -> 25000 | H38: 70000 | I38: =E38*H38 -> 70000 | J38: 200000 | K38: =E38*J38 -> 200000 | L38: МИН: прямой еврокнижка · СРЕД: угловой с независимым пружинным блоком · МАКС: модульный, ткань antiklaw | M38: https://hoff.ru/catalog/gostinaya/divany/ | N38: СРЕД | O38: =IF(N38="МИН",G38,IF(N38="МАКС",K38,I38)) -> 70000
A39: 31 | B39: Зал | C39: Телевизор | D39: шт | E39: 1 | F39: 25000 | G39: =E39*F39 -> 25000 | H39: 55000 | I39: =E39*H39 -> 55000 | J39: 150000 | K39: =E39*J39 -> 150000 | L39: МИН: 43–50" 4K (Haier/Xiaomi) · СРЕД: 55" 4K (Samsung/LG) · МАКС: 65–75" OLED/QLED | M39: https://www.dns-shop.ru/catalog/17a8ae1316404e77/televizory-i-aksessuary/ | N39: СРЕД | O39: =IF(N39="МИН",G39,IF(N39="МАКС",K39,I39)) -> 55000
A40: 32 | B40: Зал | C40: Кронштейн / ТВ-тумба | D40: компл | E40: 1 | F40: 3000 | G40: =E40*F40 -> 3000 | H40: 15000 | I40: =E40*H40 -> 15000 | J40: 50000 | K40: =E40*J40 -> 50000 | L40: закладная под кронштейн — в стену, не в потолок | M40: https://hoff.ru/catalog/mebel/ | N40: МИН | O40: =IF(N40="МИН",G40,IF(N40="МАКС",K40,I40)) -> 3000
A41: 33 | B41: Зал | C41: Журнальный стол | D41: шт | E41: 1 | F41: 3000 | G41: =E41*F41 -> 3000 | H41: 12000 | I41: =E41*H41 -> 12000 | J41: 40000 | K41: =E41*J41 -> 40000 | M41: https://hoff.ru/catalog/mebel/ | N41: МИН | O41: =IF(N41="МИН",G41,IF(N41="МАКС",K41,I41)) -> 3000
...

Sheet 3_Саммари
A1: 3. САММАРИ: СКОЛЬКО ВСЕГО НУЖНО ДЕНЕГ — квартира 55 м², Саратов
A2: Все цифры — формулы с листов 1_Ремонт и 2_Заезд. Меняйте цены там — здесь пересчитается.
A4: Блок | B4: МИН | C4: СРЕД | D4: МАКС | E4: РЕАЛ (сборка) | F4: Комментарий
A5: 1. РЕМОНТ — материалы (пол, потолок, сантехника, электрика, обои, двери) | B5: ='1_Ремонт'!G81 -> 232190 | C5: ='1_Ремонт'!I81 -> 598460 | D5: ='1_Ремонт'!K81 -> 1413650 | E5: ='1_Ремонт'!N81 -> 598460 | F5: включая натяжной потолок «под ключ»
A6: 1. РЕМОНТ — работы | B6: ='1_Ремонт'!G82 -> 125600 | C6: ='1_Ремонт'!I82 -> 235100 | D6: ='1_Ремонт'!K82 -> 420200 | E6: ='1_Ремонт'!N82 -> 235100
A7: 1. РЕМОНТ — резерв | B7: ='1_Ремонт'!G84 -> 35779 | C7: ='1_Ремонт'!I84 -> 83356 | D7: ='1_Ремонт'!K84 -> 183385 | E7: ='1_Ремонт'!N84 -> 83356 | F7: процент задаётся на листе Параметры
A8: 1. РЕМОНТ — ИТОГО | B8: ='1_Ремонт'!G85 -> 393569 | C8: ='1_Ремонт'!I85 -> 916916 | D8: ='1_Ремонт'!K85 -> 2017235 | E8: ='1_Ремонт'!N85 -> 916916 | F8: лист 1_Ремонт
A10: 2. ЗАЕЗД — закупка (кухня, мебель, техника, текстиль) | B10: ='2_Заезд'!G69 -> 451500 | C10: ='2_Заезд'!I69 -> 1207000 | D10: ='2_Заезд'!K69 -> 3352000 | E10: ='2_Заезд'!O69 -> 725500
A11: 2. ЗАЕЗД — работы (сборка, подключение, доставка) | B11: ='2_Заезд'!G70 -> 22500 | C11: ='2_Заезд'!I70 -> 65500 | D11: ='2_Заезд'!K70 -> 129000 | E11: ='2_Заезд'!O70 -> 65500
A12: 2. ЗАЕЗД — резерв | B12: ='2_Заезд'!G72 -> 47400 | C12: ='2_Заезд'!I72 -> 127250 | D12: ='2_Заезд'!K72 -> 348100 | E12: ='2_Заезд'!O72 -> 79100
A13: 2. ЗАЕЗД — ИТОГО | B13: ='2_Заезд'!G73 -> 521400 | C13: ='2_Заезд'!I73 -> 1399750 | D13: ='2_Заезд'!K73 -> 3829100 | E13: ='2_Заезд'!O73 -> 870100 | F13: лист 2_Заезд
A15: ВСЕГО МАТЕРИАЛЫ + ЗАКУПКА | B15: =B5+B10 -> 683690 | C15: =C5+C10 -> 1805460 | D15: =D5+D10 -> 4765650 | E15: =E5+E10 -> 1323960
A16: ВСЕГО РАБОТЫ | B16: =B6+B11 -> 148100 | C16: =C6+C11 -> 300600 | D16: =D6+D11 -> 549200 | E16: =E6+E11 -> 300600
A17: ВСЕГО РЕЗЕРВ | B17: =B7+B12 -> 83179 | C17: =C7+C12 -> 210606 | D17: =D7+D12 -> 531485 | E17: =E7+E12 -> 162456
A18: ОБЩИЙ ИТОГ: РЕМОНТ + ЗАЕЗД | B18: =B8+B13 -> 914969 | C18: =C8+C13 -> 2316666 | D18: =D8+D13 -> 5846335 | E18: =E8+E13 -> 1787016 | F18: с резервом
A19: На 1 м² квартиры | B19: =IF(Параметры!$B$4=0,0,B18/Параметры!$B$4) -> 16605.608 | C19: =IF(Параметры!$B$4=0,0,C18/Параметры!$B$4) -> 42044.755 | D19: =IF(Параметры!$B$4=0,0,D18/Параметры!$B$4) -> 106104.08 | E19: =IF(Параметры!$B$4=0,0,E18/Параметры!$B$4) -> 32432.232
A20: Доля ремонта в общем итоге | B20: =IF(B18=0,0,B8/B18) -> 0.43014463 | C20: =IF(C18=0,0,C8/C18) -> 0.39579119 | D20: =IF(D18=0,0,D8/D18) -> 0.34504266 | E20: =IF(E18=0,0,E8/E18) -> 0.51309893
A22: РЕАЛ (сборка) — реалистичная колонка: ремонт по СРЕД (обои флизелиновые); заезд — кухня модульная Hoff/Лемана по МИН; холодильник, ПММ, индукция, диван, ТВ, матрасы, детская кровать и стол по СРЕД, остальная мебель и мелкая техника по МИН. Меняется выпадающими списками в столбцах M (1_Ремонт) и N (2_Заезд).
A23: Учтено всё до заезда: ремонт (включая обои, двери, уборку) + кухня, мебель, техника. Входная дверь стоит — не считаем. Не учтено: окна, лоджия, стояки.
A24: Как пользоваться: 1) Параметры — площади и количества; 2) 1_Ремонт и 2_Заезд — цены под выбранные товары и выбор МИН/СРЕД/МАКС для колонки РЕАЛ; 3) закупка по ссылкам с листов Закупка_ссылки и 2_Заезд (столбец M).

Sheet Планировка
A1: ПЛАНИРОВКА ПО ПЛАНУ КВ. 312 (2-комн., 55.1 м²) И ПРАВКИ БРАТА
A3: Помещение | B3: По плану, м² | C3: После правок, м² | D3: Назначение в проекте | E3: Что изменено
A4: Спальня | B4: 11.7 | C4: 11.7 | D4: Спальня родителей + выход на лоджию | E4: —
A5: Гостиная | B5: 13.7 | C5: 12.2 | D5: ДЕТСКАЯ (изолированная комната, широкий проём — двустворчатая дверь) | E5: стена №2 сдвинута в сторону гостиной ≈ на 0.4 м (≈ –1.5 м²); проём №3 расширен
A6: Кухня | B6: 10.3 | C6: 11.8 | D6: Кухня-гостиная: кухня + обеденная зона | E6: стена №1 (кухня–прихожая) снесена; +1.5 м² от гостиной
A7: Прихожая | B7: 11.8 | C7: 11.8 | D7: Прихожая у входа (плитка) + зона зала: диван, ТВ | E7: объединена с кухней в единое пространство ≈ 23.6 м²
A8: Ванная | B8: 2.8 | C8: 2.8 | D8: Душевая с подиумом + раковина (по видео) | E8: ванна заменена на душевой подиум
A9: С/у | B9: 2.1 | C9: 2.1 | D9: Унитаз + раковина + газовая колонка (по видео) | E9: —
A10: Лоджия | B10: 2.7 | C10: 2.7 | D10: Утеплённая — кабинет/хранение | E10: —
A11: Итого без лоджии | B11: =SUM(B4:B9) -> 52.4 | C11: =SUM(C4:C9) -> 52.4
A13: Заметка брата (22.02.26): 1) стены кухня–прихожая не будет; 2) стену гостиной сдвинул к гостиной — кухня больше, потом детская; 3) дверной проём сделал широким, чтобы пространство казалось больше.
A14: Выведенные величины для сметы: ламинат 42 м², потолки 52.4 м², плинтус 50 п.м, обои 120 м², двери 3 стандартных + 1 широкая. Дизайн-концепция по 3 опциям — в отдельном документе Word.

Sheet Закупка_ссылки
A1: ЧТО ИМЕННО КУПИТЬ И ГДЕ — Саратов
A2: Ссылки ведут в каталоги магазинов с доставкой/самовывозом в Саратове. Ищите указанную модель/серию через поиск на сайте — конкретные артикулы и цены меняются, сверяйте перед оплатой.
A4: Позиция | B4: Опция | C4: Что купить (модель / серия) | D4: Ориентир цены | E4: Магазин | F4: Ссылка
A5: Напольное покрытие | B5: МИН | C5: Ламинат 32 кл 8 мм: Kronostar Symbio / Artfloor / Kronostep | D5: 700–850 ₽/м² | E5: Лемана ПРО Саратов | F5: https://saratov.lemanapro.ru/catalogue/laminat/klass-33/
A6: Напольное покрытие | B6: МИН | C6: Альтернатива: Профком Саратов, ламинат 33 кл | D6: от 700 ₽/м² | E6: Профком Саратов | F6: https://www.profkom64.ru/product/napolnie_pokritiya/laminat-33-klass/
A7: Напольное покрытие | B7: СРЕД | C7: Ламинат 33 кл 8–10 мм с фаской, влагостойкий: Egger Home / Tarkett / Kastamonu | D7: 1 000–1 400 ₽/м² | E7: Лемана ПРО Саратов | F7: https://saratov.lemanapro.ru/catalogue/laminat/klass-33/
A8: Напольное покрытие | B8: МАКС | C8: SPC-кварцвинил 43 кл 4–5 мм: Alpine Floor / Aquafloor / Quick-Step Alpha | D8: 1 800–2 800 ₽/м² | E8: Паркет73 Саратов | F8: https://saratov.parket73.ru/spc-laminat/
A9: Напольное покрытие | B9: МАКС | C9: SPC / кварцвинил, большой выбор коллекций | D9: от 1 790 ₽/м² | E9: Олимп Паркета Саратов | F9: https://saratov.olimp-parketa.ru/catalog/kvarc-vinilovyy-laminat/
A10: Подложка, плёнка, плинтус | B10: ВСЕ | C10: Подложка ПЭ 2 мм / XPS 3 мм / пробка; плёнка 200 мкм; плинтус ПВХ / МДФ / дюрополимер — раздел «Напольные покрытия» | D10: см. смету | E10: Лемана ПРО Саратов | F10: https://saratov.lemanapro.ru/
A11: Натяжной потолок | B11: МИН | C11: ПВХ матовый MSD Classic, белый, обычный профиль | D11: 300–450 ₽/м² с монтажом | E11: Потолочные компании Саратова (сравнение 72 фирм) | F11: https://saratov.potolochek.su/prices
A12: Натяжной потолок | B12: МИН/СРЕД | C12: Прайс: MSD от 293 ₽/м², Bauf от 460 ₽/м², Teqtum от 990 ₽/м² | D12: по прайсу | E12: СуперПотолок Саратов | F12: https://superpotolok.ru/ceny/
A13: Натяжной потолок | B13: СРЕД | C13: Полотно Bauf / тканевый + теневой профиль EuroKraab | D13: 800–1 100 ₽/м² | E13: РВС-Сервис Саратов | F13: https://potolki-rvs.ru/ceny
A14: Натяжной потолок | B14: МАКС | C14: Тканевый Descor/Clipso + теневой профиль + световые линии/парящий | D14: 1 500–2 500 ₽/м² | E14: НатПотолокСрт | F14: https://saratov.natpotolok.ru/matovyj-potolok
A15: Светильники | B15: ВСЕ | C15: GX53 (МИН) / точечные LED (СРЕД) / магнитный трек (МАКС) — раздел «Освещение» | D15: см. смету | E15: Лемана ПРО Саратов | F15: https://saratov.lemanapro.ru/
... A43: Щит и автоматы | B43: МАКС | C43: ABB S200 / Hager, дифавтоматы на каждую группу, реле напряжения, УЗИП | D43: 50 000–70 000 ₽ | E43: Электротовары.ру | F43: https://elektro-tovars.ru/catalog/rozetki-vyklyuchateli/schneider-electric-rozetki-vyklyuchateli

Sheet Работы_подрядчики
A1: РАСЦЕНКИ НА РАБОТЫ И ГДЕ ИСКАТЬ МАСТЕРОВ — Саратов
A3: Вид работ | B3: Ориентир цены (Саратов, 2026) | C3: Где искать | D3: Ссылка | E3: Что проверить у мастера
A4: Укладка ламината / SPC | B4: 200–500 ₽/м² (SPC и диагональ дороже) | C4: Profi.ru Саратов | D4: https://profi.ru/geo-saratov/remont/pol/ukladka-laminata/price/ | E4: перепад стяжки ≤ 2 мм на 2 м; ламинат должен отлежаться 48 ч
A5: Укладка ламината — бригада с замером | B5: от 285 ₽/м² | C5: S5R Саратов | D5: https://saratov.s5r.ru/ukladka-laminata | E5: бесплатный замер и смета
A6: Натяжные потолки под ключ | B6: 300–450 ₽/м² МИН; 800–1 100 СРЕД; 1 500+ МАКС | C6: СуперПотолок / РВС-Сервис / НатПотолокСрт | D6: https://superpotolok.ru/ceny/ | E6: обвод труб, углы, закладные — считаются отдельно, требуйте полную смету
A7: Плиточник / сантехник / электрик | B7: плиточники от 800 ₽/м²; сантехника и электрика — по точкам | C7: Profi.ru Саратов | D7: https://profi.ru/geo-saratov/remont/plitochniki/price/ | E7: паспорт проверен, отзывы, гарантия на работы
A8: Установка сантехники | B8: унитаз 2 500–4 000; раковина 2 500–4 000; смеситель душа 2 000–3 500; инсталляция 6 000–9 000 | C8: Profi.ru / Avito Саратов | D8: https://profi.ru/geo-saratov/remont/plitochniki/price/ | E8: опрессовка соединений, чек на материалы
A9: Электромонтаж | B9: розетка/выключатель 250–600 ₽; сборка щита 6 000–25 000; точка света 500–800 ₽ | C9: Profi.ru / Avito Саратов | D9: https://profi.ru/geo-saratov/remont/plitochniki/price/ | E9: схема щита на бумаге, маркировка линий, акт проверки

Sheet Видео_и_порядок
A1: ЧТО ВИДНО НА ВИДЕО И В КАКОМ ПОРЯДКЕ ДЕЛАТЬ
A3: Зона | B3: Состояние по видео | C3: Что делать | D3: Этап
A4: Пол в комнатах, кухне, коридоре у окна | B4: Ровная серая стяжка / наливной пол, чистая, без покрытия | C4: Грунт → плёнка → подложка → ламинат/SPC → плинтус | D4: 3
A5: Пол в прихожей и у санузлов | B5: Уложен крупноформатный керамогранит «под мрамор», швы затёрты | C5: Ничего. Только порожек на стыке с ламинатом | D5: 3
A6: Стены во всех комнатах | B6: Оштукатурены и зашпаклёваны (белые), не окрашены, без обоев | C6: Финиш стен — НЕ в этой смете, но делать ДО пола и ДО натяжного потолка (профиль крепится к готовым стенам) | D6: 1
A7: Потолки везде | B7: Голая плита, по ней открытая проводка и трубы, висящие провода | C7: Закрепить кабель в гофре, поставить закладные под люстры/карнизы → натяжной потолок | D7: 2 → 4
A8: Электрика | B8: Из стен торчат провода в местах розеток/выключателей; на стене санузла №1 — корпус розетки; щита в сборе не видно | C8: Собрать щит, поставить розетки/выключатели, прозвонить | D8: 2 (щит) → 5 (розетки)
A9: Санузел №1 | B9: Стены в плитке «оникс», висит газовая колонка, выводы воды и канализации готовы, стоит старый унитаз без бачка (временный), на полу трап/квадрат плитки, угловая полка | C9: Новый унитаз, раковина с тумбой и смесителем, зеркало, гигиенический душ, люк к колонке, вентилятор | D9: 5
A10: Санузел №2 (душевая) | B10: Душевой подиум с линейным трапом, отделан плиткой «под дерево», 3 полки в нише, выводы под смеситель душа и под раковину, светильник висит на проводе | C10: Смеситель + стойка, стеклянное ограждение, раковина с тумбой, полотенцесушитель, вентилятор | D10: 5
A11: Двери | B11: Межкомнатных дверей нет, проёмы пустые | C11: Двери — НЕ в этой смете; ставить ПОСЛЕ пола (этап 6) | D11: 6
A12: Отопление | B12: Радиатор под окном установлен | C12: Ничего | D12: —
A15: ПОРЯДОК РАБОТ (чтобы не переделывать)
A16: 1. Финиш стен (покраска/обои) — до потолка и до пола.
A17: 2. Электрика: сборка щита, разводка потолочных линий в гофре, закладные под люстры и карнизы. Розетки пока НЕ ставить.
A18: 3. Пол: грунт, плёнка, подложка, ламинат/SPC. Плинтус — после дверей (этап 6) либо сразу, если двери с добором.
A19: 4. Натяжные потолки (замер за 1–2 дня, монтаж 1 день на квартиру). Условие: стены готовы, точки света разведены, t в квартире ≥ +10°C.
A20: 5. Сантехника и электроустановка: унитаз, раковины, смесители, стекло душевой, полотенцесушитель, вентиляторы, розетки/выключатели, светильники.
A21: 6. Двери, плинтус, финальная уборка.
A23: ЧТО ОБЯЗАТЕЛЬНО ПОД НАТЯЖНОЙ ПОТОЛОК
A24: — Весь кабель по потолку в гофре, закреплён клипсами каждые 50 см (на видео он висит свободно).
A25: — Закладные (фанера/платформы) под каждую люстру, трек и под карниз штор — на стойках или брусе.
A26: — Штробы и дыры в потолке заделаны, вентканалы закрыты решётками.
A27: — Стены зашпаклёваны до потолка (профиль крепится к стене на дюбели каждые 10–15 см).
... A29: — В санузлах — только ПВХ (тканевый не любит влагу), обвод труб считается отдельно.

Sheet Ссылки_по_позициям
A1: ССЫЛКИ И БЕНЧМАРК ЦЕН ПО САРАТОВУ — НА КАЖДУЮ ПОЗИЦИЮ СМЕТЫ (МИН / СРЕД / МАКС)
A2: Проверка 11.09.2026: цены и ссылки собраны из каталогов магазинов Саратова и площадок с доставкой в Саратов. «Цена найдена» — то, что реально показано на странице/в поисковой выдаче на дату проверки; «Цена в смете» — из листов 1_Ремонт / 2_Заезд (не менялась). Отклонение > ±30 % выделено. Статус «уточнить» = подтверждённой цены нет, дана ссылка в каталог. Перед оплатой сверяйте цену на сайте. АВИТО: на каждую позицию есть строка «Авито Саратов» (опция ВСЕ) с готовым поиском — через Авито можно посмотреть предложения магазинов и частников по Саратову и оптимизировать стоимость относительно сметы; цены с Авито снимаются вручную (автоматическая проверка недоступна).
A3: Строк: 442 · подтверждено: 217 · уточнить: 225 (в т. ч. 110 ссылок на поиск Авито Саратов — цены снимать вручную)
A5: Лист | B5: № | C5: Раздел | D5: Позиция | E5: Ед. | F5: Опция | G5: Модель / вариант | H5: Цена найдена, ₽ | I5: Цена в смете, ₽ | J5: Отклонение, % | K5: Магазин / источник | L5: Город | M5: Ссылка | N5: Подтверждение | O5: Дата проверки | P5: Статус | Q5: Комментарий
A6: 1_Ремонт | B6: 1 | C6: 1. Пол | D6: Напольное покрытие (ламинат / SPC) | E6: м² | F6: МИН | G6: Ламинат ELEGANTE Дуб Сидамо, 33 кл (Профком) | H6: 591 | I6: 700 | J6: -15.6 | K6: Профком Саратов | L6: Саратов | M6: https://www.profkom64.ru/product/napolnie_pokritiya/laminat-33-klass/ | N6: страница | O6: 2026-09-11 | P6: ок | Q6: Дешевле сметного 32 кл; Floorpan Lagoon 705 ₽/м², Egger 735–746 ₽/м² там же
A7: 1_Ремонт | B7: 1 | C7: 1. Пол | D7: Напольное покрытие (ламинат / SPC) | E7: м² | F7: СРЕД | G7: Ламинат Aberhof Storm 8 мм, 33 кл, фаска V4 | H7: 1060 | I7: 1150 | J7: -7.8 | K7: Профком Саратов | L7: Саратов | M7: https://www.profkom64.ru/product/napolnie_pokritiya/laminat-33-klass/ | N7: страница | O7: 2026-09-11 | P7: ок | Q7: Kastamonu Sunfloor 1094; Aberhof Cruise 10 мм 1342; Tarkett Pilot 10 мм 1845 ₽/м²
A8: 1_Ремонт | B8: 1 | C8: 1. Пол | D8: Напольное покрытие (ламинат / SPC) | E8: м² | F8: МАКС | G8: SPC Akplast Royce Ultima 4,5 мм | H8: 2050 | I8: 2300 | J8: -10.9 | K8: Паркет73 Саратов | L8: Саратов | M8: https://saratov.parket73.ru/spc-laminat/ | N8: страница | O8: 2026-09-11 | P8: ок | Q8: Класс износостойкости на странице не показан; Tarkett Blackwood Stone 4,4 мм 1799; Олимп Паркета Calitex Elementals 2370 ₽/м² (https://saratov.olimp-parketa.ru/catalog/kvarc-vinilovyy-laminat/)
A9: 1_Ремонт | B9: 1 | C9: 1. Пол | D9: Напольное покрытие (ламинат / SPC) | E9: м² | F9: ВСЕ | G9: Авито Саратов — поиск «Напольное покрытие» (новые товары магазинов и объявления) | K9: Авито Саратов | L9: Саратов | M9: https://www.avito.ru/saratov?q=%D0%9D%D0%B0%D0%BF%D0%BE%D0%BB%D1%8C%D0%BD%D0%BE%D0%B5%20%D0%BF%D0%BE%D0%BA%D1%80%D1%8B%D1%82%D0%B8%D0%B5 | N9: не проверено | O9: 2026-09-11 | P9: уточнить | Q9: Через Авито можно посмотреть предложения по Саратову и оптимизировать стоимость: откройте поиск по ссылке, сравните с ценой в смете и с вариантами магазинов выше. Автоматически цены с Авито снять нельзя (доступ по IP ограничен) — смотреть вручную.
A10: 1_Ремонт | B10: 2 | C10: 1. Пол | D10: Подложка | E10: м² | F10: МИН | G10: НПЭ (вспененный ПЭ) 2 мм, рулон шир. 1,05 м | H10: 15.3 | I10: 100 | J10: -84.7 | K10: Профком Саратов | L10: Саратов | M10: https://www.profkom64.ru/product/napolnie_pokritiya/podlozhka_pod_laminat_linoleum_parket/ | N10: страница | O10: 2026-09-11 | P10: ок | Q10: 16,10 ₽/п.м при ширине 1,05 м = 15,3 ₽/м²; смета завышена в 6 раз
A11: 1_Ремонт | B11: 2 | C11: 1. Пол | D11: Подложка | E11: м² | F11: СРЕД | G11: XPS 3 мм (гармошка) / Arbiton | I11: 200 | K11: Профком Саратов | L11: Саратов | M11: https://www.profkom64.ru/product/napolnie_pokritiya/podlozhka_pod_laminat_linoleum_parket/ | N11: не проверено | O11: 2026-09-11 | P11: уточнить | Q11: Гармошка 3 мм 398 ₽/упак — площадь упаковки на странице не указана; Arbiton XPS 3 мм по сниппетам 432–1085 ₽ без подтверждённой единицы; НПЭ 3 мм 24,20 ₽/п.м (=23 ₽/м²)
A12: 1_Ремонт | B12: 2 | C12: 1. Пол | D12: Подложка | E12: м² | F12: МАКС | G12: Пробковая подложка 2 мм, рулон 10×1 м | H12: 413 | I12: 350 | J12: 18 | K12: Профком Саратов | L12: Саратов | M12: https://www.profkom64.ru/product/napolnie_pokritiya/podlozhka_pod_laminat_linoleum_parket/ | N12: страница | O12: 2026-09-11 | P12: ок | Q12: 4 131 ₽/рулон 10 м² = 413 ₽/м²; Solid PROtector Thermo SPC 1 мм 824 ₽/рулон и гармошка SPC/LVT 1,5 мм 862 ₽/упак — площадь не указана
A13: 1_Ремонт | B13: 2 | C13: 1. Пол | D13: Подложка | E13: м² | F13: ВСЕ | G13: Авито Саратов — поиск «Подложка» (новые товары магазинов и объявления) | K13: Авито Саратов | L13: Саратов | M13: https://www.avito.ru/saratov?q=%D0%9F%D0%BE%D0%B4%D0%BB%D0%BE%D0%B6%D0%BA%D0%B0 | N13: не проверено | O13: 2026-09-11 | P13: уточнить | Q13: Через Авито можно посмотреть предложения по Саратову и оптимизировать стоимость: откройте поиск по ссылке, сравните с ценой в смете и с вариантами магазинов выше. Автоматически цены с Авито снять нельзя (доступ по IP ограничен) — смотреть вручную.
A14: 1_Ремонт | B14: 3 | C14: 1. Пол | D14: Плёнка пароизоляция 200 мкм | E14: м² | F14: МИН | G14: Плёнка полиэтиленовая 200 мкм (категория) | H14: 14 | I14: 30 | J14: -53.3 | K14: Бикра-М (Москва) | L14: доставка в Саратов | M14: https://bikra-m.ru/guard/plenka-ograzhdeniya-i-ukrytiya/plenka/200-mkm/ | N14: сниппет | O14: 2026-09-11 | P14: уточнить | Q14: «от 14 ₽/м²» в заголовке; московский поставщик, доставка в Саратов не проверена
A15: 1_Ремонт | B15: 3 | C15: 1. Пол | D15: Плёнка пароизоляция 200 мкм | E15: м² | F15: СРЕД | G15: Плёнка п/э 200 мк прозрачная, рулон 100 м | I15: 40 | K15: Профком Саратов | L15: Саратов | M15: https://www.profkom64.ru/product/utepliteli/paroizol_plenka/plenka_200_prozrachnaya.html | N15: сниппет | O15: 2026-09-11 | P15: уточнить | Q15: 72 ₽/п.м по сниппету; ширина рулона не указана (при рукаве 1,5 м ≈ 24 ₽/м² — допущение)
A16: 1_Ремонт | B16: 3 | C16: 1. Пол | D16: Плёнка пароизоляция 200 мкм | E16: м² | F16: МАКС | G16: Плёнки строительные 200 мкм (категория) | I16: 40 | K16: Лемана ПРО | L16: доставка в Саратов | M16: https://lemanapro.ru/catalogue/plenki-stroitelnye/200-mkm/ | N16: сниппет | O16: 2026-09-11 | P16: уточнить | Q16: Каталог «от 581 ₽» за рулон, размер рулона не указан; саратовский каталог блокирует доступ (401)
A17: 1_Ремонт | B17: 3 | C17: 1. Пол | D17: Плёнка пароизоляция 200 мкм | E17: м² | F17: ВСЕ | G17: Авито Саратов — поиск «Плёнка пароизоляция 200 мкм» (новые товары магазинов и объявления) | K17: Авито Саратов | L17: Саратов | M17: https://www.avito.ru/saratov?q=%D0%9F%D0%BB%D1%91%D0%BD%D0%BA%D0%B0%20%D0%BF%D0%B0%D1%80%D0%BE%D0%B8%D0%B7%D0%BE%D0%BB%D1%8F%D1%86%D0%B8%D1%8F%20200%20%D0%BC%D0%BA%D0%BC | N17: не проверено | O17: 2026-09-11 | P17: уточнить | Q17: Через Авито можно посмотреть предложения по Саратову и оптимизировать стоимость: откройте поиск по ссылке, сравните с ценой в смете и с вариантами магазинов выше. Автоматически цены с Авито снять нельзя (доступ по IP ограничен) — смотреть вручную.
A18: 1_Ремонт | B18: 4 | C18: 1. Пол | D18: Плинтус напольный | E18: п.м | F18: МИН | G18: ПВХ Идеал Комфорт 55 мм с кабель-каналом | H18: 85 | I18: 130 | J18: -34.6 | K18: Профком (Энгельс/Саратов) | L18: Саратов | M18: https://engels.profkom64.ru/product/napolnie_pokritiya/plintus/ | N18: страница | O18: 2026-09-11 | P18: уточнить | Q18: 73–85 ₽/шт; длина хлыста на странице не указана (обычно 2,5 м ≈ 34 ₽/п.м — допущение); заглушки 29–45 ₽/пара
A19: 1_Ремонт | B19: 4 | C19: 1. Пол | D19: Плинтус напольный | E19: п.м | F19: СРЕД | G19: Дюрополимер Decomaster A036 100×16 под покраску | H19: 339 | I19: 350 | J19: -3.1 | K19: Про-плинтус.ру | L19: доставка в Саратов | M19: https://pro-plintys.ru/a036plintusartprofilnapolnyyizdyuropolimerapodpokrasku100x16 | N19: сниппет | O19: 2026-09-11 | P19: ок | Q19: 339 ₽/м (хлыст 2 м); МДФ в Лемана ПРО «от 368 ₽» (единица не указана), polvdome МДФ от 150 ₽/п.м
A20: 1_Ремонт | B20: 4 | C20: 1. Пол | D20: Плинтус напольный | E20: п.м | F20: МАКС | G20: Скрытый (теневой) алюминиевый плинтус | I20: 800 | K20: Лемана ПРО | L20: доставка в Саратов | M20: https://lemanapro.ru/catalogue/napolnye-plintusy/tenevye/ | N20: сниппет | O20: 2026-09-11 | P20: уточнить | Q20: Каталог «от 800 ₽», единица (шт/п.м) не указана; adv-parket теневой «от 560 ₽»; pro-plintus FD-04.1 42×14×2500 без цены в сниппете
A21: 1_Ремонт | B21: 4 | C21: 1. Пол | D21: Плинтус напольный | E21: п.м | F21: ВСЕ | G21: Авито Саратов — поиск «Плинтус напольный» (новые товары магазинов и объявления) | K21: Авито Саратов | L21: Саратов | M21: https://www.avito.ru/saratov?q=%D0%9F%D0%BB%D0%B8%D0%BD%D1%82%D1%83%D1%81%20%D0%BD%D0%B0%D0%BF%D0%BE%D0%BB%D1%8C%D0%BD%D1%8B%D0%B9 | N21: не проверено | O21: 2026-09-11 | P21: уточнить | Q21: Через Авито можно посмотреть предложения по Саратову и оптимизировать стоимость: откройте поиск по ссылке, сравните с ценой в смете и с вариантами магазинов выше. Автоматически цены с Авито снять нельзя (доступ по IP ограничен) — смотреть вручную.
A22: 1_Ремонт | B22: 5 | C22: 1. Пол | D22: Порожки, стыки плитка–ламинат | E22: компл | F22: МИН | G22: 3× порог скрытый Artens 30×900 мм, 0–8 мм | H22: 681 | I22: 1500 | J22: -54.6 | K22: Лемана ПРО (цена Самара) | L22: доставка в Саратов | M22: https://samara.lemanapro.ru/product/porog-raznourovnevyy-kant-artens-skrytyy-17855099/ | N22: сниппет | O22: 2026-09-11 | P22: уточнить | Q22: 227 ₽/шт × 3 стыка (коридор + 2 санузла — допущение); цена в Самаре, Саратов блокирует доступ
A23: 1_Ремонт | B23: 5 | C23: 1. Пол | D23: Порожки, стыки плитка–ламинат | E23: компл | F23: СРЕД | G23: 3× порог разноуровневый алюминиевый ПР06 900×41, закрытый крепёж | H23: 2955 | I23: 3000 | J23: -1.5 | K23: Лемана ПРО (цена Тверь) | L23: доставка в Саратов | M23: https://tver.lemanapro.ru/product/porog-dlya-pola-raznourovnevyy-alyuminievyy-pr06-zakrytyy-krepezh-900x41-perepad-belyy-matovyy-91155692/ | N23: сниппет | O23: 2026-09-11 | P23: уточнить | Q23: 985 ₽/шт × 3; количество стыков — допущение
A24: 1_Ремонт | B24: 5 | C24: 1. Пол | D24: Порожки, стыки плитка–ламинат | E24: компл | F24: МАКС | G24: Т-образный / скрытый порог по размеру, пробковый компенсатор | I24: 6000 | K24: Лемана ПРО | L24: доставка в Саратов | M24: https://lemanapro.ru/catalogue/porozhki-dlya-pola/raznourovnevye/ | N24: не проверено | O24: 2026-09-11 | P24: уточнить | Q24: Цен на заказные порожки не найдено; каталог разноуровневых «от 230 ₽»
A25: 1_Ремонт | B25: 5 | C25: 1. Пол | D25: Порожки, стыки плитка–ламинат | E25: компл | F25: ВСЕ | G25: Авито Саратов — поиск «Порожки, стыки плитка–ламинат» (новые товары магазинов и объявления) | K25: Авито Саратов | L25: Саратов | M25: https://www.avito.ru/saratov?q=%D0%9F%D0%BE%D1%80%D0%BE%D0%B6%D0%BA%D0%B8%2C%20%D1%81%D1%82%D1%8B%D0%BA%D0%B8%20%D0%BF%D0%BB%D0%B8%D1%82%D0%BA%D0%B0%E2%80%93%D0%BB%D0%B0%D0%BC%D0%B8%D0%BD%D0%B0%D1%82 | N25: не проверено | O25: 2026-09-11 | P25: уточнить | Q25: Через Авито можно посмотреть предложения по Саратову и оптимизировать стоимость: откройте поиск по ссылке, сравните с ценой в смете и с вариантами магазинов выше. Автоматически цены с Авито снять нельзя (доступ по IP ограничен) — смотреть вручную.
A26: 1_Ремонт | B26: 6 | C26: 2. Потолок | D26: Натяжной потолок с монтажом «под ключ» | E26: м² | F26: МИН | G26: ПВХ матовый белый HALEAD, обычный профиль, с монтажом | H26: 380 | I26: 400 | J26: -5 | K26: РВС-Сервис Саратов | L26: Саратов | M26: https://potolki-rvs.ru/ceny | N26: страница | O26: 2026-09-11 | P26: ок | Q26: 380 ₽/м² от 30 м² (400 до 18 м²); СуперПотолок MSD «от 293 ₽/м²» (https://superpotolok.ru/ceny/)
A27: 1_Ремонт | B27: 6 | C27: 2. Потолок | D27: Натяжной потолок с монтажом «под ключ» | E27: м² | F27: СРЕД | G27: Bauf (ширина >3,6 м) с монтажом + теневой профиль | H27: 590 | I27: 950 | J27: -37.9 | K27: СуперПотолок Саратов | L27: Саратов | M27: https://superpotolok.ru/ceny/ | N27: страница | O27: 2026-09-11 | P27: уточнить | Q27: 590 ₽/м² только полотно с монтажом (460 до 3,6 м); теневой профиль отдельно: Хоум Комфорт 150–340 ₽/п.м + монтаж 650–1000 ₽/п.м (https://xn--80aagvjfuafcrkii.xn--p1ai/tenevoj-natyazhnoj-potolok/); zabor.bz «теневой от 488 ₽/м²»
A28: 1_Ремонт | B28: 6 | C28: 2. Потолок | D28: Натяжной потолок с монтажом «под ключ» | E28: м² | F28: МАКС | G28: Тканевый Descor D-premium белый с монтажом | H28: 1800 | I28: 1800 | J28: 0 | K28: РВС-Сервис Саратов | L28: Саратов | M28: https://potolki-rvs.ru/ceny | N28: страница | O28: 2026-09-11 | P28: ок | Q28: Descor белый 1500, D-premium 1650–1800 ₽/м²; световые линии/контурная подсветка +900 ₽/п.м, ниша с подсветкой 4200 ₽/п.м; СуперПотолок Descor от 2700 ₽/м²
A29: 1_Ремонт | B29: 6 | C29: 2. Потолок | D29: Натяжной потолок с монтажом «под ключ» | E29: м² | F29: ВСЕ | G29: Авито Саратов — поиск «Натяжной потолок с монтажом «под ключ»» (новые товары магазинов и объявления) | K29: Авито Саратов | L29: Саратов | M29: https://www.avito.ru/saratov?q=%D0%9D%D0%B0%D1%82%D1%8F%D0%B6%D0%BD%D0%BE%D0%B9%20%D0%BF%D0%BE%D1%82%D0%BE%D0%BB%D0%BE%D0%BA%20%D1%81%20%D0%BC%D0%BE%D0%BD%D1%82%D0%B0%D0%B6%D0%BE%D0%BC%20%C2%AB%D0%BF%D0%BE%D0%B4%20%D0%BA%D0%BB%D1%8E%D1%87%C2%BB | N29: не проверено | O29: 2026-09-11 | P29: уточнить | Q29: Через Авито можно посмотреть предложения по Саратову и оптимизировать стоимость: откройте поиск по ссылке, сравните с ценой в смете и с вариантами магазинов выше. Автоматически цены с Авито снять нельзя (доступ по IP ограничен) — смотреть вручную.
A30: 1_Ремонт | B30: 7 | C30: 2. Потолок | D30: Закладные (брус/платформы) под люстры, карнизы | E30: компл | F30: МИН | G30: 2 платформы под люстру (420 ₽) + закладная под карниз 3 м (550 ₽/м) | H30: 2490 | I30: 2000 | J30: 24.5 | K30: РВС-Сервис Саратов | L30: Саратов | M30: https://potolki-rvs.ru/ceny | N30: страница | O30: 2026-09-11 | P30: уточнить | Q30: Состав комплекта — допущение; в прайсе это «установка светильника 420 ₽» и «карниз 550 ₽/м»
A31: 1_Ремонт | B31: 7 | C31: 2. Потолок | D31: Закладные (брус/платформы) под люстры, карнизы | E31: компл | F31: СРЕД | G31: Точка монтажа 550 ₽; встраиваемый светильник до 350 мм 1200 ₽, свыше 1500 ₽ | I31: 4000 | K31: СуперПотолок Саратов | L31: Саратов | M31: https://superpotolok.ru/ceny/ | N31: страница | O31: 2026-09-11 | P31: уточнить | Q31: Закладная под карниз в прайсе не выделена; сумма комплекта не собирается без состава
A32: 1_Ремонт | B32: 7 | C32: 2. Потолок | D32: Закладные (брус/платформы) под люстры, карнизы | E32: компл | F32: МАКС | G32: Усиленные закладные + ниша под карниз | I32: 8000 | K32: РВС-Сервис Саратов | L32: Саратов | M32: https://potolki-rvs.ru/potolki/nisha-pod-karniz.html | N32: не проверено | O32: 2026-09-11 | P32: уточнить | Q32: Отдельной цены нет; ориентир РВС «ниша с подсветкой 4200 ₽/п.м»
A33: 1_Ремонт | B33: 7 | C33: 2. Потолок | D33: Закладные (брус/платформы) под люстры, карнизы | E33: компл | F33: ВСЕ | G33: Авито Саратов — поиск «Закладные под люстры, карнизы» (новые товары магазинов и объявления) | K33: Авито Саратов | L33: Саратов | M33: https://www.avito.ru/saratov?q=%D0%97%D0%B0%D0%BA%D0%BB%D0%B0%D0%B4%D0%BD%D1%8B%D0%B5%20%D0%BF%D0%BE%D0%B4%20%D0%BB%D1%8E%D1%81%D1%82%D1%80%D1%8B%2C%20%D0%BA%D0%B0%D1%80%D0%BD%D0%B8%D0%B7%D1%8B | N33: не проверено | O33: 2026-09-11 | P33: уточнить | Q33: Через Авито можно посмотреть предложения по Саратову и оптимизировать стоимость: откройте поиск по ссылке, сравните с ценой в смете и с вариантами магазинов выше. Автоматически цены с Авито снять нельзя (доступ по IP ограничен) — смотреть вручную.
A34: 1_Ремонт | B34: 8 | C34: 2. Потолок | D34: Кабель ВВГнг-LS + гофра для потолочных линий | E34: компл | F34: МИН | G34: 100 м ВВГнг-LS 3×1,5 (43,5 ₽/м) + 100 м гофра Экопласт D16 (991 ₽) | H34: 5341 | I34: 6000 | J34: -11 | K34: Ламповед + Лемана ПРО (цена Ростов) | L34: доставка в Саратов | M34: https://www.lampoved.ru/kabeli/vvgng/vvgngls315 | N34: сниппет | O34: 2026-09-11 | P34: уточнить | Q34: Метраж 100+100 м — допущение; гофра https://rostov.lemanapro.ru/product/truba-gofrirovannaya-ekoplast-d16-mm-100-m-pvh-legkaya-s-protyazhkoy-cvet-seryy-10056016/
A35: 1_Ремонт | B35: 8 | C35: 2. Потолок | D35: Кабель ВВГнг-LS + гофра для потолочных линий | E35: компл | F35: СРЕД | G35: ВВГнг(А)-LS 3×1,5 уп.100 м Русский Свет (10 302,9 ₽) + гофра DKC D16 100 м (1 798 ₽) | H35: 12101 | I35: 12000 | J35: 0.8 | K35: Русский Свет (rs24) + Лемана ПРО (цена Краснодар) | L35: доставка в Саратов | M35: https://rs24.ru/product/2962068 | N35: сниппет | O35: 2026-09-11 | P35: уточнить | Q35: Метраж — допущение; саратовский МегаVольт (volt64.ru): ВВГнг 3×1,5 (без LS) 90 ₽/м; гофра https://krasnodar.lemanapro.ru/product/truba-gofrirovannaya-dkc-d16-mm-100-m-pvh-legkaya-s-protyazhkoy-cvet-seryy-85174899/
A36: 1_Ремонт | B36: 8 | C36: 2. Потолок | D36: Кабель ВВГнг-LS + гофра для потолочных линий | E36: компл | F36: МАКС | G36: 100 м ВВГнг(А)-LS 3×1,5 Конкорд ЭТМ (104,24 ₽/м) + 2×50 м гофра DKC D25 (2 354 ₽, Лемана Саратов) | H36: 15132 | I36: 20000 | J36: -24.3 | K36: ЭТМ + Лемана ПРО Саратов | L36: Саратов | M36: https://www.etm.ru/cat/nn/9729228 | N36: сниппет | O36: 2026-09-11 | P36: уточнить | Q36: Метраж — допущение; гофра D25 https://saratov.lemanapro.ru/product/truba-gofrirovannaya-s-protyazhkoy-dkc-pvh-d25-mm-50-m-legkaya-cvet-chernyy-91538362/
A37: 1_Ремонт | B37: 8 | C37: 2. Потолок | D37: Кабель ВВГнг-LS + гофра для потолочных линий | E37: компл | F37: ВСЕ | G37: Авито Саратов — поиск «Кабель ВВГнг-LS + гофра для потолочных линий» (новые товары магазинов и объявления) | K37: Авито Саратов | L37: Саратов | M37: https://www.avito.ru/saratov?q=%D0%9A%D0%B0%D0%B1%D0%B5%D0%BB%D1%8C%20%D0%92%D0%92%D0%93%D0%BD%D0%B3-LS%20%2B%20%D0%B3%D0%BE%D1%84%D1%80%D0%B0%20%D0%B4%D0%BB%D1%8F%20%D0%BF%D0%BE%D1%82%D0%BE%D0%BB%D0%BE%D1%87%D0%BD%D1%8B%D1%85%20%D0%BB%D0%B8%D0%BD%D0%B8%D0%B9 | N37: не проверено | O37: 2026-09-11 | P37: уточнить | Q37: Через Авито можно посмотреть предложения по Саратову и оптимизировать стоимость: откройте поиск по ссылке, сравните с ценой в смете и с вариантами магазинов выше. Автоматически цены с Авито снять нельзя (доступ по IP ограничен) — смотреть вручную.
A38: 1_Ремонт | B38: 9 | C38: 2. Потолок | D38: Светильники потолочные | E38: шт | F38: МИН | G38: Накладной Ecola GX53 DGX5318 белый | H38: 82 | I38: 250 | J38: -67.2 | K38: ВсеИнструменты | L38: доставка в Саратов | M38: https://www.vseinstrumenti.ru/electrika-i-svet/svetilniki/nastenno-potolochnye/nakladnye/ecola/gx53-dgx5318-legkij-belyj-svetilnik-18x83-fw53ffecd/ | N38: сниппет | O38: 2026-09-11 | P38: ок | Q38: Без лампы; лампа Uniel GX53 8 Вт 81 ₽ в Лемана Саратов (https://saratov.lemanapro.ru/product/lampa-svetodiodnaya-uniel-gx53-8-vt-670-lm-svet-holodnyy-belyy-18336805/) → 163 ₽ с лампой
A39: 1_Ремонт | B39: 9 | C39: 2. Потолок | D39: Светильники потолочные | E39: шт | F39: СРЕД | G39: Встраиваемый LED Apeyron 06-17, отв. 85 мм | H39: 615 | I39: 700 | J39: -12.1 | K39: Лемана ПРО Саратов | L39: Саратов | M39: https://saratov.lemanapro.ru/product/svetilnik-tochechnyy-svetodiodnyy-vstraivaemyy-apeyron-06-17-pod-otverstie-85-mm-88110327/ | N39: сниппет | O39: 2026-09-11 | P39: ок | Q39: Люстра Семь огней Трине 8 ламп 3 558 ₽ там же (для 2 люстр по смете)
A40: 1_Ремонт | B40: 9 | C40: 2. Потолок | D40: Светильники потолочные | E40: шт | F40: МАКС | G40: Магнитный трековый светильник 48V (Spot ET48 18W и аналоги) | I40: 2500 | K40: Лемана ПРО | L40: доставка в Саратов | M40: https://lemanapro.ru/catalogue/trekovye-sistemy-osveshcheniya/magnitnye-vstraivaemye/ | N40: сниппет | O40: 2026-09-11 | P40: уточнить | Q40: Категория «от 900–988 ₽» без цены конкретной модели; шинопровод и блок питания в смете не выделены
A41: 1_Ремонт | B41: 9 | C41: 2. Потолок | D41: Светильники потолочные | E41: шт | F41: ВСЕ | G41: Авито Саратов — поиск «Светильники потолочные» (новые товары магазинов и объявления) | K41: Авито Саратов | L41: Саратов | M41: https://www.avito.ru/saratov?q=%D0%A1%D0%B2%D0%B5%D1%82%D0%B8%D0%BB%D1%8C%D0%BD%D0%B8%D0%BA%D0%B8%20%D0%BF%D0%BE%D1%82%D0%BE%D0%BB%D0%BE%D1%87%D0%BD%D1%8B%D0%B5 | N41: не проверено | O41: 2026-09-11 | P41: уточнить | Q41: Через Авито можно посмотреть предложения по Саратову и оптимизировать стоимость: откройте поиск по ссылке, сравните с ценой в смете и с вариантами магазинов выше. Автоматически цены с Авито снять нельзя (доступ по IP ограничен) — смотреть вручную.
...
